ply
format ascii 1.0
comment : MagicaVoxel @ Ephtracy
element vertex 398
property float x
property float y
property float z
property uchar red
property uchar green
property uchar blue
end_header
-10 0 10 221 221 221
-2 1 8 255 153 0
-3 1 8 255 153 0
2 2 12 119 119 119
1 -3 10 187 187 187
-3 0 6 0 153 51
-3 3 9 119 119 119
-4 0 9 119 119 119
-5 0 3 255 204 153
-3 -2 9 255 153 0
-3 0 10 136 136 136
-9 0 7 85 85 85
-3 -1 11 136 136 136
-3 -2 7 255 153 0
-3 1 3 51 204 51
-4 0 12 119 119 119
-3 -1 9 204 153 51
-1 3 11 119 119 119
2 1 12 119 119 119
3 1 12 136 136 136
-2 0 0 153 102 51
-1 2 6 255 153 0
-4 0 4 51 153 102
2 0 12 136 136 136
-2 2 3 51 204 51
-3 2 7 255 153 0
-1 -1 7 255 153 102
-3 -2 12 119 119 119
3 0 12 136 136 136
-6 0 8 204 153 102
-6 0 5 153 102 51
-3 0 3 0 153 51
2 -1 12 136 136 136
-1 2 12 119 119 119
6 2 4 255 153 0
-1 1 13 136 136 136
3 -1 12 136 136 136
-2 -3 11 170 170 170
-10 0 7 170 170 170
-2 1 4 51 204 51
-1 0 3 0 153 51
-7 0 9 85 85 85
0 -2 12 136 136 136
1 -2 12 136 136 136
-4 -1 10 119 119 119
2 -2 12 136 136 136
-2 -2 12 136 136 136
-4 -2 10 119 119 119
-2 3 11 119 119 119
-6 0 10 204 153 102
-1 -1 3 0 153 51
-2 0 8 255 153 0
-1 0 9 255 153 0
-4 -2 9 119 119 119
-2 4 9 119 119 119
-2 -3 10 170 170 170
-3 1 7 255 153 0
-8 0 5 170 170 170
-2 0 4 0 153 51
6 0 6 255 153 0
-1 -1 5 0 153 51
-4 -2 11 119 119 119
-1 -3 10 170 170 170
4 0 13 136 136 136
0 -3 10 187 187 187
2 -3 10 187 187 187
-2 0 9 255 153 0
-6 0 9 85 85 85
4 0 14 170 170 170
2 3 11 119 119 119
-8 0 10 170 170 170
-1 0 13 136 136 136
-3 0 5 255 204 153
-3 -2 3 0 153 51
3 2 11 136 136 136
-3 1 9 255 153 0
-2 -2 10 136 136 136
2 1 11 136 136 136
-8 0 8 119 119 119
-4 0 8 119 119 119
-2 0 2 255 204 153
-2 1 13 119 119 119
3 0 11 136 136 136
-4 1 8 119 119 119
2 -1 11 136 136 136
-4 1 12 119 119 119
3 -2 11 136 136 136
0 4 10 119 119 119
-1 3 9 119 119 119
-5 0 14 136 136 136
1 4 10 119 119 119
-3 -3 10 170 170 170
-3 3 11 119 119 119
3 0 13 136 136 136
-3 3 10 119 119 119
-3 -1 8 255 204 51
2 3 10 119 119 119
3 2 10 136 136 136
-1 1 3 0 153 51
3 1 10 136 136 136
-3 2 8 136 136 136
2 0 10 136 136 136
-2 -1 13 119 119 119
-3 0 8 255 153 0
3 -1 10 136 136 136
0 -2 10 136 136 136
-2 -1 3 51 204 51
-9 0 10 85 85 85
-3 2 3 0 153 51
-2 4 10 119 119 119
2 2 10 255 153 0
-8 0 12 221 221 221
1 -2 10 136 136 136
-3 -1 12 119 119 119
-1 -3 11 170 170 170
-1 2 3 0 153 51
3 -2 10 136 136 136
0 4 9 119 119 119
1 4 9 119 119 119
2 -1 10 255 153 0
0 -3 11 187 187 187
-2 0 13 119 119 119
2 3 9 119 119 119
-2 3 8 119 119 119
-3 -1 6 255 153 0
3 2 9 136 136 136
2 1 9 255 153 0
-2 2 6 255 153 0
-2 2 12 119 119 119
3 0 9 136 136 136
-1 4 10 119 119 119
2 1 10 255 153 0
2 -2 10 255 153 0
-2 -2 6 255 153 0
-6 0 6 153 102 51
2 -1 9 204 153 51
-2 -1 7 255 153 102
-1 2 7 255 153 0
-2 3 7 255 153 0
-4 -1 8 119 119 119
-6 0 0 153 102 51
2 -2 9 255 153 0
-1 2 8 119 119 119
-2 1 3 51 204 51
-2 4 8 119 119 119
3 -2 9 136 136 136
-2 0 1 153 102 51
-7 0 8 85 85 85
1 4 8 119 119 119
-2 3 9 255 153 0
-1 1 10 255 153 0
-3 -2 8 255 153 0
2 2 8 136 136 136
-9 0 9 85 85 85
-2 -1 5 51 204 51
-6 0 7 153 102 51
3 1 8 136 136 136
-3 0 7 255 153 0
3 0 8 136 136 136
-1 -1 8 255 204 153
-10 0 8 170 170 170
-3 2 12 119 119 119
-1 2 10 255 153 0
-4 0 13 119 119 119
-2 -1 4 51 204 51
-1 -1 4 0 153 51
-3 1 10 255 153 0
-4 1 10 119 119 119
-2 2 10 255 153 0
-2 -1 8 17 17 17
-4 2 9 119 119 119
1 -3 11 187 187 187
2 -1 8 255 153 0
-2 -1 9 255 153 0
-4 2 11 119 119 119
-3 0 12 119 119 119
-2 1 5 51 204 51
-1 4 9 119 119 119
-1 1 4 0 153 51
3 -1 8 136 136 136
-4 0 11 119 119 119
-1 1 8 255 153 0
2 -2 8 255 153 0
-2 -2 3 51 204 51
-9 0 11 221 221 221
-3 2 10 255 153 0
-1 3 6 255 153 0
-4 -1 12 119 119 119
-8 0 9 170 170 170
-2 2 9 255 153 0
2 2 7 255 153 0
7 1 5 255 153 0
3 1 7 255 153 0
2 -3 11 238 238 238
-3 1 11 119 119 119
-8 0 7 119 119 119
2 0 7 255 153 51
-1 -2 9 255 153 0
0 -2 11 255 153 0
-4 2 10 119 119 119
-1 -2 11 255 153 0
-5 0 13 119 119 119
-9 0 8 85 85 85
-1 1 5 0 153 51
-3 -1 3 51 204 51
-1 -1 6 51 204 0
2 -2 7 255 153 0
2 1 8 255 153 0
-1 -2 12 136 136 136
-3 1 6 255 153 0
-9 0 6 170 170 170
-6 0 2 153 102 51
-1 -2 3 0 153 51
-6 0 3 153 102 51
-3 -1 5 255 153 0
-10 0 9 221 221 221
-2 -2 11 255 153 0
-6 0 4 153 102 51
-1 -1 13 136 136 136
-6 0 1 153 102 51
-3 1 12 119 119 119
5 3 3 255 153 0
2 3 6 255 153 0
-3 -3 11 170 170 170
-3 -2 11 255 153 0
-2 -1 10 255 153 0
-2 1 12 255 153 0
-1 1 12 255 153 0
-2 1 10 255 153 0
2 -2 3 51 204 51
1 -2 3 0 153 51
0 -2 3 51 204 51
2 -1 3 0 153 51
-2 2 8 255 153 0
-2 0 12 255 153 0
3 0 3 255 204 153
2 0 3 51 204 51
2 2 6 255 153 0
-1 -1 9 255 153 0
2 1 3 0 153 51
2 0 9 255 153 0
-2 -1 12 255 153 0
2 2 3 51 204 51
-1 -1 12 255 153 0
-2 0 10 255 153 0
3 3 3 255 153 0
-1 0 10 255 153 0
-3 2 11 255 153 0
4 0 4 255 204 153
-2 2 11 255 153 0
4 2 6 255 153 0
-3 0 9 255 153 0
-1 -2 10 255 153 0
4 3 4 255 153 0
2 3 4 255 153 0
2 -1 5 255 153 0
2 2 11 255 153 0
-2 1 11 255 153 0
3 0 5 255 204 153
-1 1 11 255 153 0
2 1 6 255 153 0
-1 1 9 255 153 0
-3 0 11 255 153 0
-2 0 11 255 153 0
3 3 5 255 153 0
-1 0 11 255 153 0
1 -2 6 255 153 0
2 -1 6 255 153 0
2 0 6 0 153 51
2 2 9 255 153 0
-1 0 12 255 153 0
-2 0 3 255 153 0
-1 2 11 255 153 0
-1 0 4 255 153 0
-3 -2 10 255 153 0
-1 0 5 255 153 0
-2 0 5 255 153 0
-2 1 9 255 153 0
-2 -1 6 255 153 0
2 0 11 255 153 0
-2 -1 11 255 153 0
-1 0 6 255 153 0
-2 0 6 255 153 0
-1 -1 11 255 153 0
-3 -1 10 255 153 0
-1 1 6 255 153 0
-2 1 6 255 153 0
1 -2 11 255 153 0
2 -2 11 255 153 0
-1 0 7 255 153 0
-2 0 7 255 153 0
2 1 7 255 153 0
-2 3 10 255 153 0
-1 3 10 255 153 0
-1 1 7 255 153 0
-2 1 7 255 153 0
-1 2 9 255 153 0
-2 2 7 255 153 0
2 0 8 255 153 0
-3 2 9 255 153 0
-1 -1 10 255 153 0
-1 0 8 255 153 0
1 0 0 153 102 51
1 0 1 153 102 51
1 0 2 255 204 153
1 -1 3 0 153 51
0 -1 3 51 204 51
1 0 3 255 153 0
0 0 3 51 204 51
1 1 3 0 153 51
0 1 3 51 204 51
1 2 3 0 153 51
0 2 3 51 204 51
1 -1 4 0 153 51
0 -1 4 51 204 51
1 0 4 51 204 51
0 0 4 255 153 0
1 1 4 0 153 51
0 1 4 51 204 51
1 -1 5 51 204 51
0 -1 5 51 204 51
1 0 5 51 153 102
0 0 5 255 153 0
1 1 5 51 153 102
0 1 5 51 204 51
1 2 5 102 153 51
1 3 5 255 153 0
1 -1 6 255 153 0
0 -1 6 51 204 51
1 0 6 255 153 0
0 0 6 255 153 0
1 1 6 255 153 0
0 1 6 255 153 0
1 2 6 255 153 51
0 2 6 255 153 0
0 3 6 255 153 0
1 -1 7 255 204 153
0 -1 7 255 204 153
1 0 7 255 153 0
0 0 7 255 153 0
1 1 7 255 153 0
0 1 7 255 153 0
1 2 7 255 153 0
0 2 7 255 153 0
1 3 7 255 153 0
1 -1 8 17 17 17
0 -1 8 255 204 153
1 0 8 255 153 0
0 0 8 255 153 0
1 1 8 255 153 0
0 1 8 255 153 0
1 2 8 255 153 0
0 2 8 119 119 119
1 3 8 119 119 119
1 -1 9 255 153 0
0 -1 9 255 153 0
1 0 9 255 153 0
0 0 9 255 153 0
1 1 9 255 153 0
0 1 9 255 153 0
1 2 9 255 153 0
0 2 9 255 153 0
1 3 9 255 153 0
0 3 9 119 119 119
1 -1 10 255 153 0
0 -1 10 255 153 0
1 0 10 255 153 0
0 0 10 255 153 0
1 1 10 255 153 0
0 1 10 255 153 0
1 2 10 255 153 0
0 2 10 255 153 0
1 3 10 255 153 0
0 3 10 255 153 0
1 -1 11 255 153 0
0 -1 11 255 153 0
1 0 11 255 153 0
0 0 11 255 153 0
1 1 11 255 153 0
0 1 11 255 153 0
1 2 11 255 153 0
0 2 11 255 153 0
1 3 11 119 119 119
0 3 11 119 119 119
1 -1 12 255 153 0
0 -1 12 255 153 0
1 0 12 255 153 0
0 0 12 255 153 0
1 1 12 255 153 0
0 1 12 255 153 0
1 2 12 119 119 119
0 2 12 119 119 119
1 -1 13 136 136 136
0 -1 13 136 136 136
1 0 13 136 136 136
0 0 13 136 136 136
1 1 13 136 136 136
0 1 13 136 136 136
